<?xml version="1.0" encoding="UTF-8"?>
<!-- Generated by org.testng.reporters.JUnitReportReporter -->
<testsuite hostname="DESKTOP-0PBS36T" name="tests.LoginTests" tests="4" failures="3" timestamp="30 Dec 2020 05:37:44 GMT" time="242.727" errors="1">
  <testcase name="successfulLogin" time="83.115" classname="tests.LoginTests">
    <error type="org.openqa.selenium.TimeoutException" message="No connection could be made because the target machine actively refused it. (os error 10061)
Build info: version: &#039;3.141.59&#039;, revision: &#039;e82be7d358&#039;, time: &#039;2018-11-14T08:25:48&#039;
System info: host: &#039;DESKTOP-0PBS36T&#039;, ip: &#039;192.168.1.9&#039;, os.name: &#039;Windows 10&#039;, os.arch: &#039;amd64&#039;, os.version: &#039;10.0&#039;, java.version: &#039;1.8.0_171&#039;
Driver info: driver.version: FirefoxDriver
remote stacktrace: ">
      <![CDATA[org.openqa.selenium.TimeoutException: No connection could be made because the target machine actively refused it. (os error 10061)
Build info: version: '3.141.59', revision: 'e82be7d358', time: '2018-11-14T08:25:48'
System info: host: 'DESKTOP-0PBS36T', ip: '192.168.1.9', os.name: 'Windows 10', os.arch: 'amd64', os.version: '10.0', java.version: '1.8.0_171'
Driver info: driver.version: FirefoxDriver
remote stacktrace: 
	at sun.reflect.NativeConstructorAccessorImpl.newInstance0(Native Method)
	at sun.reflect.NativeConstructorAccessorImpl.newInstance(Unknown Source)
	at sun.reflect.DelegatingConstructorAccessorImpl.newInstance(Unknown Source)
	at java.lang.reflect.Constructor.newInstance(Unknown Source)
	at org.openqa.selenium.remote.W3CHandshakeResponse.lambda$errorHandler$0(W3CHandshakeResponse.java:62)
	at org.openqa.selenium.remote.HandshakeResponse.lambda$getResponseFunction$0(HandshakeResponse.java:30)
	at org.openqa.selenium.remote.ProtocolHandshake.lambda$createSession$0(ProtocolHandshake.java:126)
	at java.util.stream.ReferencePipeline$3$1.accept(Unknown Source)
	at java.util.Spliterators$ArraySpliterator.tryAdvance(Unknown Source)
	at java.util.stream.ReferencePipeline.forEachWithCancel(Unknown Source)
	at java.util.stream.AbstractPipeline.copyIntoWithCancel(Unknown Source)
	at java.util.stream.AbstractPipeline.copyInto(Unknown Source)
	at java.util.stream.AbstractPipeline.wrapAndCopyInto(Unknown Source)
	at java.util.stream.FindOps$FindOp.evaluateSequential(Unknown Source)
	at java.util.stream.AbstractPipeline.evaluate(Unknown Source)
	at java.util.stream.ReferencePipeline.findFirst(Unknown Source)
	at org.openqa.selenium.remote.ProtocolHandshake.createSession(ProtocolHandshake.java:128)
	at org.openqa.selenium.remote.ProtocolHandshake.createSession(ProtocolHandshake.java:74)
	at org.openqa.selenium.remote.HttpCommandExecutor.execute(HttpCommandExecutor.java:136)
	at org.openqa.selenium.remote.service.DriverCommandExecutor.execute(DriverCommandExecutor.java:83)
	at org.openqa.selenium.remote.RemoteWebDriver.execute(RemoteWebDriver.java:552)
	at org.openqa.selenium.remote.RemoteWebDriver.startSession(RemoteWebDriver.java:213)
	at org.openqa.selenium.remote.RemoteWebDriver.<init>(RemoteWebDriver.java:131)
	at org.openqa.selenium.firefox.FirefoxDriver.<init>(FirefoxDriver.java:147)
	at org.openqa.selenium.firefox.FirefoxDriver.<init>(FirefoxDriver.java:125)
	at tests.LoginTests.launchApp(LoginTests.java:139)
	at tests.LoginTests.successfulLogin(LoginTests.java:45)
	at sun.reflect.NativeMethodAccessorImpl.invoke0(Native Method)
	at sun.reflect.NativeMethodAccessorImpl.invoke(Unknown Source)
	at sun.reflect.DelegatingMethodAccessorImpl.invoke(Unknown Source)
	at java.lang.reflect.Method.invoke(Unknown Source)
	at org.testng.internal.MethodInvocationHelper.invokeMethod(MethodInvocationHelper.java:100)
	at org.testng.internal.Invoker.invokeMethod(Invoker.java:646)
	at org.testng.internal.Invoker.invokeTestMethod(Invoker.java:811)
	at org.testng.internal.Invoker.invokeTestMethods(Invoker.java:1129)
	at org.testng.internal.TestMethodWorker.invokeTestMethods(TestMethodWorker.java:129)
	at org.testng.internal.TestMethodWorker.run(TestMethodWorker.java:112)
	at org.testng.TestRunner.privateRun(TestRunner.java:746)
	at org.testng.TestRunner.run(TestRunner.java:600)
	at org.testng.SuiteRunner.runTest(SuiteRunner.java:366)
	at org.testng.SuiteRunner.runSequentially(SuiteRunner.java:361)
	at org.testng.SuiteRunner.privateRun(SuiteRunner.java:319)
	at org.testng.SuiteRunner.run(SuiteRunner.java:268)
	at org.testng.SuiteRunnerWorker.runSuite(SuiteRunnerWorker.java:52)
	at org.testng.SuiteRunnerWorker.run(SuiteRunnerWorker.java:86)
	at org.testng.TestNG.runSuitesSequentially(TestNG.java:1264)
	at org.testng.TestNG.runSuitesLocally(TestNG.java:1189)
	at org.testng.TestNG.runSuites(TestNG.java:1104)
	at org.testng.TestNG.run(TestNG.java:1076)
	at org.testng.remote.AbstractRemoteTestNG.run(AbstractRemoteTestNG.java:126)
	at org.testng.remote.RemoteTestNG.initAndRun(RemoteTestNG.java:152)
	at org.testng.remote.RemoteTestNG.main(RemoteTestNG.java:57)
]]>
    </error>
  </testcase> <!-- successfulLogin -->
  <testcase name="successfulLogin" time="55.394" classname="tests.LoginTests">
    <failure type="java.lang.AssertionError" message="expected [https://opensource-demo.orangehrmlive.com/index.php/dashboard] but found [https://opensource-demo.orangehrmlive.com/index.php/auth/validateCredentials]">
      <![CDATA[java.lang.AssertionError: expected [https://opensource-demo.orangehrmlive.com/index.php/dashboard] but found [https://opensource-demo.orangehrmlive.com/index.php/auth/validateCredentials]
	at org.testng.Assert.fail(Assert.java:94)
	at org.testng.Assert.failNotEquals(Assert.java:513)
	at org.testng.Assert.assertEqualsImpl(Assert.java:135)
	at org.testng.Assert.assertEquals(Assert.java:116)
	at org.testng.Assert.assertEquals(Assert.java:190)
	at org.testng.Assert.assertEquals(Assert.java:200)
	at tests.LoginTests.successfulLogin(LoginTests.java:53)
	at sun.reflect.NativeMethodAccessorImpl.invoke0(Native Method)
	at sun.reflect.NativeMethodAccessorImpl.invoke(Unknown Source)
	at sun.reflect.DelegatingMethodAccessorImpl.invoke(Unknown Source)
	at java.lang.reflect.Method.invoke(Unknown Source)
	at org.testng.internal.MethodInvocationHelper.invokeMethod(MethodInvocationHelper.java:100)
	at org.testng.internal.Invoker.invokeMethod(Invoker.java:646)
	at org.testng.internal.Invoker.retryFailed(Invoker.java:958)
	at org.testng.internal.Invoker.invokeTestMethods(Invoker.java:1147)
	at org.testng.internal.TestMethodWorker.invokeTestMethods(TestMethodWorker.java:129)
	at org.testng.internal.TestMethodWorker.run(TestMethodWorker.java:112)
	at org.testng.TestRunner.privateRun(TestRunner.java:746)
	at org.testng.TestRunner.run(TestRunner.java:600)
	at org.testng.SuiteRunner.runTest(SuiteRunner.java:366)
	at org.testng.SuiteRunner.runSequentially(SuiteRunner.java:361)
	at org.testng.SuiteRunner.privateRun(SuiteRunner.java:319)
	at org.testng.SuiteRunner.run(SuiteRunner.java:268)
	at org.testng.SuiteRunnerWorker.runSuite(SuiteRunnerWorker.java:52)
	at org.testng.SuiteRunnerWorker.run(SuiteRunnerWorker.java:86)
	at org.testng.TestNG.runSuitesSequentially(TestNG.java:1264)
	at org.testng.TestNG.runSuitesLocally(TestNG.java:1189)
	at org.testng.TestNG.runSuites(TestNG.java:1104)
	at org.testng.TestNG.run(TestNG.java:1076)
	at org.testng.remote.AbstractRemoteTestNG.run(AbstractRemoteTestNG.java:126)
	at org.testng.remote.RemoteTestNG.initAndRun(RemoteTestNG.java:152)
	at org.testng.remote.RemoteTestNG.main(RemoteTestNG.java:57)
]]>
    </failure>
  </testcase> <!-- successfulLogin -->
  <testcase name="successfulLogin" time="38.092" classname="tests.LoginTests">
    <failure type="java.lang.AssertionError" message="expected [https://opensource-demo.orangehrmlive.com/index.php/dashboard] but found [https://opensource-demo.orangehrmlive.com/index.php/auth/validateCredentials]">
      <![CDATA[java.lang.AssertionError: expected [https://opensource-demo.orangehrmlive.com/index.php/dashboard] but found [https://opensource-demo.orangehrmlive.com/index.php/auth/validateCredentials]
	at org.testng.Assert.fail(Assert.java:94)
	at org.testng.Assert.failNotEquals(Assert.java:513)
	at org.testng.Assert.assertEqualsImpl(Assert.java:135)
	at org.testng.Assert.assertEquals(Assert.java:116)
	at org.testng.Assert.assertEquals(Assert.java:190)
	at org.testng.Assert.assertEquals(Assert.java:200)
	at tests.LoginTests.successfulLogin(LoginTests.java:53)
	at sun.reflect.NativeMethodAccessorImpl.invoke0(Native Method)
	at sun.reflect.NativeMethodAccessorImpl.invoke(Unknown Source)
	at sun.reflect.DelegatingMethodAccessorImpl.invoke(Unknown Source)
	at java.lang.reflect.Method.invoke(Unknown Source)
	at org.testng.internal.MethodInvocationHelper.invokeMethod(MethodInvocationHelper.java:100)
	at org.testng.internal.Invoker.invokeMethod(Invoker.java:646)
	at org.testng.internal.Invoker.retryFailed(Invoker.java:958)
	at org.testng.internal.Invoker.invokeTestMethods(Invoker.java:1147)
	at org.testng.internal.TestMethodWorker.invokeTestMethods(TestMethodWorker.java:129)
	at org.testng.internal.TestMethodWorker.run(TestMethodWorker.java:112)
	at org.testng.TestRunner.privateRun(TestRunner.java:746)
	at org.testng.TestRunner.run(TestRunner.java:600)
	at org.testng.SuiteRunner.runTest(SuiteRunner.java:366)
	at org.testng.SuiteRunner.runSequentially(SuiteRunner.java:361)
	at org.testng.SuiteRunner.privateRun(SuiteRunner.java:319)
	at org.testng.SuiteRunner.run(SuiteRunner.java:268)
	at org.testng.SuiteRunnerWorker.runSuite(SuiteRunnerWorker.java:52)
	at org.testng.SuiteRunnerWorker.run(SuiteRunnerWorker.java:86)
	at org.testng.TestNG.runSuitesSequentially(TestNG.java:1264)
	at org.testng.TestNG.runSuitesLocally(TestNG.java:1189)
	at org.testng.TestNG.runSuites(TestNG.java:1104)
	at org.testng.TestNG.run(TestNG.java:1076)
	at org.testng.remote.AbstractRemoteTestNG.run(AbstractRemoteTestNG.java:126)
	at org.testng.remote.RemoteTestNG.initAndRun(RemoteTestNG.java:152)
	at org.testng.remote.RemoteTestNG.main(RemoteTestNG.java:57)
]]>
    </failure>
  </testcase> <!-- successfulLogin -->
  <testcase name="successfulLogin" time="66.126" classname="tests.LoginTests">
    <failure type="java.lang.AssertionError" message="expected [https://opensource-demo.orangehrmlive.com/index.php/dashboard] but found [https://opensource-demo.orangehrmlive.com/index.php/auth/validateCredentials]">
      <![CDATA[java.lang.AssertionError: expected [https://opensource-demo.orangehrmlive.com/index.php/dashboard] but found [https://opensource-demo.orangehrmlive.com/index.php/auth/validateCredentials]
	at org.testng.Assert.fail(Assert.java:94)
	at org.testng.Assert.failNotEquals(Assert.java:513)
	at org.testng.Assert.assertEqualsImpl(Assert.java:135)
	at org.testng.Assert.assertEquals(Assert.java:116)
	at org.testng.Assert.assertEquals(Assert.java:190)
	at org.testng.Assert.assertEquals(Assert.java:200)
	at tests.LoginTests.successfulLogin(LoginTests.java:53)
	at sun.reflect.NativeMethodAccessorImpl.invoke0(Native Method)
	at sun.reflect.NativeMethodAccessorImpl.invoke(Unknown Source)
	at sun.reflect.DelegatingMethodAccessorImpl.invoke(Unknown Source)
	at java.lang.reflect.Method.invoke(Unknown Source)
	at org.testng.internal.MethodInvocationHelper.invokeMethod(MethodInvocationHelper.java:100)
	at org.testng.internal.Invoker.invokeMethod(Invoker.java:646)
	at org.testng.internal.Invoker.retryFailed(Invoker.java:958)
	at org.testng.internal.Invoker.invokeTestMethods(Invoker.java:1147)
	at org.testng.internal.TestMethodWorker.invokeTestMethods(TestMethodWorker.java:129)
	at org.testng.internal.TestMethodWorker.run(TestMethodWorker.java:112)
	at org.testng.TestRunner.privateRun(TestRunner.java:746)
	at org.testng.TestRunner.run(TestRunner.java:600)
	at org.testng.SuiteRunner.runTest(SuiteRunner.java:366)
	at org.testng.SuiteRunner.runSequentially(SuiteRunner.java:361)
	at org.testng.SuiteRunner.privateRun(SuiteRunner.java:319)
	at org.testng.SuiteRunner.run(SuiteRunner.java:268)
	at org.testng.SuiteRunnerWorker.runSuite(SuiteRunnerWorker.java:52)
	at org.testng.SuiteRunnerWorker.run(SuiteRunnerWorker.java:86)
	at org.testng.TestNG.runSuitesSequentially(TestNG.java:1264)
	at org.testng.TestNG.runSuitesLocally(TestNG.java:1189)
	at org.testng.TestNG.runSuites(TestNG.java:1104)
	at org.testng.TestNG.run(TestNG.java:1076)
	at org.testng.remote.AbstractRemoteTestNG.run(AbstractRemoteTestNG.java:126)
	at org.testng.remote.RemoteTestNG.initAndRun(RemoteTestNG.java:152)
	at org.testng.remote.RemoteTestNG.main(RemoteTestNG.java:57)
]]>
    </failure>
  </testcase> <!-- successfulLogin -->
</testsuite> <!-- tests.LoginTests -->
